/mnt/appl/software/PyTorch/1.10.0-foss-2021a-CUDA-11.3.1/lib/python3.9/site-packages/torch/distributed/launch.py:178: FutureWarning: The module torch.distributed.launch is deprecated
and will be removed in future. Use torchrun.
Note that --use_env is set by default in torchrun.
If your script expects `--local_rank` argument to be set, please
change it to read from `os.environ['LOCAL_RANK']` instead. See 
https://pytorch.org/docs/stable/distributed.html#launch-utility for 
further instructions

  warnings.warn(
WARNING:torch.distributed.run:
*****************************************
Setting OMP_NUM_THREADS environment variable for each process to be 1 in default, to avoid your system being overloaded, please further tune the variable for optimal performance in your application as needed. 
*****************************************
train_uda.py --local_rank=1 --config_path configs/data_config/da_kitti_poss/uda_kitti_poss_f2_2_time.yaml
Namespace(config_path='configs/data_config/da_kitti_poss/uda_kitti_poss_f2_2_time.yaml', mgpus=False, local_rank=1)
distributed: True
train_uda.py --local_rank=0 --config_path configs/data_config/da_kitti_poss/uda_kitti_poss_f2_2_time.yaml
Namespace(config_path='configs/data_config/da_kitti_poss/uda_kitti_poss_f2_2_time.yaml', mgpus=False, local_rank=0)
distributed: True
[480 360  32]
[480 360  32]
[480 360  32]
[480 360  32]
|-------------------------Training started-----------------------------------------|
focal_loss:False, weighted_cross_entropy: False
|-------------------------Training started-----------------------------------------|
focal_loss:False, weighted_cross_entropy: False
  0%|          | 0/4783 [00:00<?, ?it/s]  0%|          | 0/4783 [00:00<?, ?it/s]Traceback (most recent call last):
  File "/home/gebreawe/Code/Segmentation/T-UDA/train_uda.py", line 367, in <module>
    main(args)
  File "/home/gebreawe/Code/Segmentation/T-UDA/train_uda.py", line 186, in main
    trainer.uda_fit(train_hypers["max_num_epochs"],
  File "/home/gebreawe/Code/Segmentation/T-UDA/utils/trainer_function.py", line 304, in uda_fit
    loss.backward()
  File "/mnt/appl/software/PyTorch/1.10.0-foss-2021a-CUDA-11.3.1/lib/python3.9/site-packages/torch/_tensor.py", line 307, in backward
    torch.autograd.backward(self, gradient, retain_graph, create_graph, inputs=inputs)
  File "/mnt/appl/software/PyTorch/1.10.0-foss-2021a-CUDA-11.3.1/lib/python3.9/site-packages/torch/autograd/__init__.py", line 154, in backward
    Variable._execution_engine.run_backward(
RuntimeError: CUDA out of memory. Tried to allocate 1.90 GiB (GPU 1; 39.41 GiB total capacity; 31.95 GiB already allocated; 1.62 GiB free; 36.42 GiB reserved in total by PyTorch) If reserved memory is >> allocated memory try setting max_split_size_mb to avoid fragmentation.  See documentation for Memory Management and PYTORCH_CUDA_ALLOC_CONF
  0%|          | 0/4783 [02:36<?, ?it/s]
WARNING:torch.distributed.elastic.multiprocessing.api:Sending process 4128990 closing signal SIGTERM
ERROR:torch.distributed.elastic.multiprocessing.api:failed (exitcode: 1) local_rank: 1 (pid: 4128991) of binary: /mnt/appl/software/Python/3.9.5-GCCcore-10.3.0/bin/python
Traceback (most recent call last):
  File "/mnt/appl/software/Python/3.9.5-GCCcore-10.3.0/lib/python3.9/runpy.py", line 197, in _run_module_as_main
    return _run_code(code, main_globals, None,
  File "/mnt/appl/software/Python/3.9.5-GCCcore-10.3.0/lib/python3.9/runpy.py", line 87, in _run_code
    exec(code, run_globals)
  File "/mnt/appl/software/PyTorch/1.10.0-foss-2021a-CUDA-11.3.1/lib/python3.9/site-packages/torch/distributed/launch.py", line 193, in <module>
    main()
  File "/mnt/appl/software/PyTorch/1.10.0-foss-2021a-CUDA-11.3.1/lib/python3.9/site-packages/torch/distributed/launch.py", line 189, in main
    launch(args)
  File "/mnt/appl/software/PyTorch/1.10.0-foss-2021a-CUDA-11.3.1/lib/python3.9/site-packages/torch/distributed/launch.py", line 174, in launch
    run(args)
  File "/mnt/appl/software/PyTorch/1.10.0-foss-2021a-CUDA-11.3.1/lib/python3.9/site-packages/torch/distributed/run.py", line 710, in run
    elastic_launch(
  File "/mnt/appl/software/PyTorch/1.10.0-foss-2021a-CUDA-11.3.1/lib/python3.9/site-packages/torch/distributed/launcher/api.py", line 131, in __call__
    return launch_agent(self._config, self._entrypoint, list(args))
  File "/mnt/appl/software/PyTorch/1.10.0-foss-2021a-CUDA-11.3.1/lib/python3.9/site-packages/torch/distributed/launcher/api.py", line 259, in launch_agent
    raise ChildFailedError(
torch.distributed.elastic.multiprocessing.errors.ChildFailedError: 
============================================================
train_uda.py FAILED
------------------------------------------------------------
Failures:
  <NO_OTHER_FAILURES>
------------------------------------------------------------
Root Cause (first observed failure):
[0]:
  time      : 2022-08-15_15:11:58
  host      : g01
  rank      : 1 (local_rank: 1)
  exitcode  : 1 (pid: 4128991)
  error_file: <N/A>
  traceback : To enable traceback see: https://pytorch.org/docs/stable/elastic/errors.html
============================================================
